Workbook

Sheet FInal table formatted
A1: Soil properties | B1: Nitrate (mmol/kg) | C1: Manganese (mmol/kg) | D1: Iron (mmol/kg) | E1: Sulphates (mmol/kg) | F1: Nitrate (kJ available/kg) | G1: Manganese (kJ available/kg) | H1: Iron (kJ available/kg) | I1: Sulphate (kJ available/kg) | J1: Total available energy to be gained by bezene oxidation (in kJ) | K1: pH | L1: Conductivity (dS/m)
A2: SC1 | B2: 0.12579651 | C2: 2.0022571 | D2: 83.079678 | E2: 0.54132834 | F2: -312.185 | G2: -2246.7994 | H2: -1453.8944 | I2: -113.19427 | J2: -4126.0731 | K2: 8.85 | L2: 0.084
A3: SC2 | B3: 0.14514982 | C3: 2.7303506 | D3: 158.10206 | E3: 1.0514262 | F3: -360.21347 | G3: -3063.8174 | H3: -2766.786 | I3: -154.35582 | J3: -6345.1727 | K3: 8.58 | L3: 0.123
A4: SC3 | B4: 0 | C4: 0.98292621 | D4: 66.606983 | E4: 2.5400791 | F4: 0 | G4: -1102.9743 | H4: -1165.6222 | I4: -55.568095 | J4: -2324.1646 | K4: 8.13 | L4: 0.149
A5: SC4 | B5: 0 | C5: 1.1831519 | D5: 56.401074 | E5: 0.63501978 | F5: 0 | G5: -1327.6542 | H5: -987.0188 | I5: -66.887522 | J5: -2381.5605 | K5: 8.3 | L5: 0.064
A6: SC5 | B6: 0 | C6: 1.3287706 | D6: 61.772605 | E6: 1.4782428 | F6: 0 | G6: -1491.0578 | H6: -1081.0206 | I6: -75.119832 | J6: -2647.1982 | K6: 8.04 | L6: 0.068
A7: SC6 | B7: 0.10321765 | C7: 2.9305763 | D7: 38.675022 | E7: 1.6760358 | F7: -256.1518 | G7: -3288.4973 | H7: -676.81289 | I7: -165.67525 | J7: -4387.1373 | K7: 7.86 | L7: 0.068
A11: Soil properties | B11: Nitrate (kJ available/kg) | C11: Manganese (kJ available/kg) | D11: Iron (kJ available/kg) | E11: Sulphate (kJ available/kg) | G11: Soil properties | H11: Nitrate (how much mole of benzene can be oxidised) | I11: Manganese (how much mole of benzene can be oxidised) | J11: Iron (how much mole of benzene can be oxidised) | K11: Sulphate (how much mole of benzene can be oxidised)
A12: SC1 | B12: 312.185 | C12: 2246.7994 | D12: 1453.8944 | E12: 30.603095 | G12: SC1 | H12: 0.10483042 | I12: 1.0678704
A13: SC2 | B13: 360.21347 | C13: 3063.8174 | D13: 2766.786 | E13: 59.440627 | G13: SC2 | H13: 0.12095818 | I13: 1.456187
A14: SC3 | B14: 0 | C14: 1102.9743 | D14: 1165.6222 | E14: 143.59914 | G14: SC3 | H14: 0 | I14: 0.52422731
A15: SC4 | B15: 0 | C15: 1327.6542 | D15: 987.0188 | E15: 35.899785 | G15: SC4 | H15: 0 | I15: 0.63101436
A16: SC5 | B16: 0 | C16: 1491.0578 | D16: 1081.0206 | E16: 83.569991 | G16: SC5 | H16: 0 | I16: 0.70867766
A17: SC6 | B17: 256.1518 | C17: 3288.4973 | D17: 676.81289 | E17: 94.751891 | G17: SC6 | H17: 0.086014707 | I17: 1.562974
A19: Taking into account bioavailable Maganese/Iron (minimal measurements, considered to be limit of bioavailability)
A20: Soil properties | B20: Nitrate (kJ available/kg) | C20: Manganese (kJ available/kg) | D20: Iron (kJ available/kg) | E20: Sulphate (kJ available/kg)
A21: SC1 | B21: 312.185 | C21: =C12-C14 -> 1143.8252 | D21: =D12-D17 -> 777.08147 | E21: 113.19427
A22: SC2 | B22: 360.21347 | C22: =C13-C14 -> 1960.8431 | D22: =D13-D17 -> 2089.9731 | E22: 154.35582
A23: SC3 | B23: 0 | C23: =C14-C14 -> 0 | D23: =D14-D17 -> 488.80931 | E23: 55.568095
A24: SC4 | B24: 0 | C24: =C15-C14 -> 224.67994 | D24: =D15-D17 -> 310.20591 | E24: 66.887522
A25: SC5 | B25: 0 | C25: =C16-C14 -> 388.08354 | D25: =D16-D17 -> 404.2077 | E25: 75.119832
A26: SC6 | B26: 256.1518 | C26: =C17-C14 -> 2185.5231 | D26: =D17-D17 -> 0 | E26: 165.67525

Sheet Acceptable_Potential
E1: Number of electrons accepted per mole (in mol) | F1: Total mmol electrons 'acceptable' for this compound | G1: Gibs free energy after oxidising 1 benzene using this electron acceptor | H1: How much mole is consumed per mmole of benzene | I1: how many moles of benzene can be oxidised using this electron acceptor
B2: Soil properties | D2: Nitrate (mmol/kg) | E2: 5 | G2: -2.978 | H2: 6
B3: SC1 | D3: 0.12579651 | E3: 5 | F3: =D3*E3 -> 0.62898255 | G3: -2.978 | H3: 6 | I3: =D3/H3 -> 0.020966085
B4: SC2 | D4: 0.14514982 | E4: 5 | F4: =D4*E4 -> 0.72574909 | G4: -2.978 | H4: 6 | I4: =D4/H4 -> 0.024191636
B5: SC3 | D5: 0 | E5: 5 | F5: =D5*E5 -> 0 | G5: -2.978 | H5: 6 | I5: =D5/H5 -> 0
B6: SC4 | D6: 0 | E6: 5 | F6: =D6*E6 -> 0 | G6: -2.978 | H6: 6 | I6: =D6/H6 -> 0
B7: SC5 | D7: 0 | E7: 5 | F7: =D7*E7 -> 0 | G7: -2.978 | H7: 6 | I7: =D7/H7 -> 0
B8: SC6 | D8: 0.10321765 | E8: 5 | F8: =D8*E8 -> 0.51608824 | G8: -2.978 | H8: 6 | I8: =D8/H8 -> 0.017202941
E10: Number of electrons accepted per mole (in mol) | F10: Total mmol electrons 'acceptable' for this compound | G10: Gibs free energy after oxidising 1 benzene using this electron acceptor | H10: How much mmole is consumed per mole of benzene
D11: Manganese (mmol/kg) | E11: 2 | G11: -2104 | H11: 15
B12: SC1 | D12: 2.0022571 | E12: 2 | F12: =D12*E12 -> 4.0045142 | G12: -2104 | H12: 15 | I12: =F12/H12 -> 0.26696761
B13: SC2 | D13: 2.7303506 | E13: 2 | F13: =D13*E13 -> 5.4607012 | G13: -2104 | H13: 15 | I13: =F13/H13 -> 0.36404674
B14: SC3 | D14: 0.98292621 | E14: 2 | F14: =D14*E14 -> 1.9658524 | G14: -2104 | H14: 15 | I14: =F14/H14 -> 0.13105683
B15: SC4 | D15: 1.1831519 | E15: 2 | F15: =D15*E15 -> 2.3663038 | G15: -2104 | H15: 15 | I15: =F15/H15 -> 0.15775359
B16: SC5 | D16: 1.3287706 | E16: 2 | F16: =D16*E16 -> 2.6575412 | G16: -2104 | H16: 15 | I16: =F16/H16 -> 0.17716942
B17: SC6 | D17: 2.9305763 | E17: 2 | F17: =D17*E17 -> 5.8611526 | G17: -2104 | H17: 15 | I17: =F17/H17 -> 0.3907435
E19: Number of electrons accepted per mole (in mol) | F19: Total mmol electrons 'acceptable' for this compound | G19: Gibs free energy after oxidising 1 benzene using this electron acceptor | H19: How much mmole is consumed per mole of benzene
D20: Iron (mmol/kg) | E20: 1 | G20: -525 | H20: 30
B21: SC1 | D21: 83.079678 | E21: 1 | F21: =D21*E21 -> 83.079678 | G21: -525 | H21: 30 | I21: =F21/H21 -> 2.7693226
B22: SC2 | D22: 158.10206 | E22: 1 | F22: =D22*E22 -> 158.10206 | G22: -525 | H22: 30 | I22: =F22/H22 -> 5.2700686
B23: SC3 | D23: 66.606983 | E23: 1 | F23: =D23*E23 -> 66.606983 | G23: -525 | H23: 30 | I23: =F23/H23 -> 2.2202328
B24: SC4 | D24: 56.401074 | E24: 1 | F24: =D24*E24 -> 56.401074 | G24: -525 | H24: 30 | I24: =F24/H24 -> 1.8800358
B25: SC5 | D25: 61.772605 | E25: 1 | F25: =D25*E25 -> 61.772605 | G25: -525 | H25: 30 | I25: =F25/H25 -> 2.0590868
B26: SC6 | D26: 38.675022 | E26: 1 | F26: =D26*E26 -> 38.675022 | G26: -525 | H26: 30 | I26: =F26/H26 -> 1.2891674
E29: Number of electrons accepted per mole (in mol) | F29: Total mmol electrons 'acceptable' for this compound | H29: How much mmole is consumed per mole of benzene
D30: Sulphates (mmol/kg) | E30: 8 | G30: Gibs free energy after oxidising 1 benzene using this electron acceptor | H30: 3.75
B31: SC1 | D31: 0.54132834 | E31: 8 | F31: =D31*E31 -> 4.3306267 | G31: -106 | H31: 3.75 | I31: =F31/H31 -> 1.1548338
B32: SC2 | D32: 1.0514262 | E32: 8 | F32: =D32*E32 -> 8.4114095 | G32: -106 | H32: 3.75 | I32: =F32/H32 -> 2.2430425
B33: SC3 | D33: 2.5400791 | E33: 8 | F33: =D33*E33 -> 20.320633 | G33: -106 | H33: 3.75 | I33: =F33/H33 -> 5.4188355
B34: SC4 | D34: 0.63501978 | E34: 8 | F34: =D34*E34 -> 5.0801582 | G34: -106 | H34: 3.75 | I34: =F34/H34 -> 1.3547089
B35: SC5 | D35: 1.4782428 | E35: 8 | F35: =D35*E35 -> 11.825942 | G35: -106 | H35: 3.75 | I35: =F35/H35 -> 3.1535846
B36: SC6 | D36: 1.6760358 | E36: 8 | F36: =D36*E36 -> 13.408286 | G36: -106 | H36: 3.75 | I36: =F36/H36 -> 3.5755431
B42: Soil properties | D42: Nitrate (mmol/kg) | E42: how many mmoles of benzene can be oxidised using this electron acceptor | F42: Gibs free energy after oxidising 1mole benzene using this electron acceptor | G42: Manganese (mmol/kg) | H42: how many mmoles of benzene can be oxidised using this electron acceptor | I42: Gibs free energy after oxidising 1 benzene using this electron acceptor | J42: Iron (mmol/kg) | K42: how many mmoles of benzene can be oxidised using this electron acceptor | L42: Gibs free energy after oxidising 1 benzene using this electron acceptor | M42: Sulphates (mmol/kg) | N42: how many mmoles of benzene can be oxidised using this electron acceptor | O42: Gibs free energy after oxidising 1 benzene using this electron acceptor
B43: SC1 | D43: 0.12579651 | E43: 0.10483042 | F43: -2978 | G43: 2.0022571 | H43: 0.26696761 | I43: -2104 | J43: 83.079678 | K43: 2.7693226 | L43: -525 | M43: 0.54132834 | N43: 1.1548338 | O43: -106
B44: SC2 | D44: 0.14514982 | E44: 0.12095818 | F44: -2978 | G44: 2.7303506 | H44: 0.36404674 | I44: -2104 | J44: 158.10206 | K44: 5.2700686 | L44: -525 | M44: 1.0514262 | N44: 2.2430425 | O44: -106
B45: SC3 | D45: 0 | E45: 0 | F45: -2978 | G45: 0.98292621 | H45: 0.13105683 | I45: -2104 | J45: 66.606983 | K45: 2.2202328 | L45: -525 | M45: 2.5400791 | N45: 5.4188355 | O45: -106
B46: SC4 | D46: 0 | E46: 0 | F46: -2978 | G46: 1.1831519 | H46: 0.15775359 | I46: -2104 | J46: 56.401074 | K46: 1.8800358 | L46: -525 | M46: 0.63501978 | N46: 1.3547089 | O46: -106
B47: SC5 | D47: 0 | E47: 0 | F47: -2978 | G47: 1.3287706 | H47: 0.17716942 | I47: -2104 | J47: 61.772605 | K47: 2.0590868 | L47: -525 | M47: 1.4782428 | N47: 3.1535846 | O47: -106
B48: SC6 | D48: 0.10321765 | E48: 0.086014707 | F48: -2978 | G48: 2.9305763 | H48: 0.3907435 | I48: -2104 | J48: 38.675022 | K48: 1.2891674 | L48: -525 | M48: 1.6760358 | N48: 3.5755431 | O48: -106
D49: Amount of energy available from using nitrate as electron acceptor | G49: Amount of energy available from using Mangenese as electron acceptor | J49: Amount of energy available from using Iron as electron acceptor | M49: Amount of energy available from using Iron as electron acceptor | R49: theoretical energy available if all electron acceptors are consumed for benzene oxidation
...

Sheet clean_version
A1: Nitrate | C1: Measured (mg/kg) | D1: g/kg | E1: Molar mass | F1: Mol/kg | G1: How many moles of e- acceptor is consumed per mole? | H1: Mole of benzene that can be oxidised with this amount of e- acceptor (in mol/kg) | I1: standart free energy changes per mole of benzene oxidised (kJ/mol) | J1: How much energy is available if this electron acceptor is consumed oxidising benzene (kJ/kg) | K1: mmol of benzene that can be consumed (mmol/kg) | L1: how many g of bezene is this? | N1: in mg benzene | O1: Energy available in J/kg
E2: in g/mol unit | F2: (mass in gram /molar mass) | G2: Based on stoichiometric equation | H2: Divide available mole / number of moles that need to be consumed per mole of benzene | I2: Can be found in table with the reactions | J2: Moles of benzene (mol/kg)* standart free energy (kJ/mol) | K2: Because it is easier to interpret | L2: 78.11 | M2: <- molar mass benzene
A3: SC1 | C3: 7.8 | D3: =C3/1000 -> 0.0078 | E3: 62 | F3: =D3/E3 -> 0.00012580645 | G3: 6 | H3: =F3/G3 -> 2.0967742e-05 | I3: 2978 | J3: =H3*I3 -> 0.062441935 | K3: =H3*1000 -> 0.020967742 | L3: =H3*$L$2 -> 0.0016377903 | N3: =L3*1000 -> 1.6377903 | O3: =J3*1000 -> 62.441935
A4: SC2 | C4: 9 | D4: =C4/1000 -> 0.009 | E4: 62 | F4: =D4/E4 -> 0.00014516129 | G4: 6 | H4: =F4/G4 -> 2.4193548e-05 | I4: 2978 | J4: =H4*I4 -> 0.072048387 | K4: =H4*1000 -> 0.024193548 | L4: =H4*$L$2 -> 0.0018897581 | N4: =L4*1000 -> 1.8897581 | O4: =J4*1000 -> 72.048387
A5: SC3 | C5: 0 | D5: =C5/1000 -> 0 | E5: 62 | F5: =D5/E5 -> 0 | G5: 6 | H5: =F5/G5 -> 0 | I5: 2978 | J5: =H5*I5 -> 0 | K5: =H5*1000 -> 0 | L5: =H5*$L$2 -> 0 | N5: =L5*1000 -> 0 | O5: =J5*1000 -> 0
A6: SC4 | C6: 0 | D6: =C6/1000 -> 0 | E6: 62 | F6: =D6/E6 -> 0 | G6: 6 | H6: =F6/G6 -> 0 | I6: 2978 | J6: =H6*I6 -> 0 | K6: =H6*1000 -> 0 | L6: =H6*$L$2 -> 0 | N6: =L6*1000 -> 0 | O6: =J6*1000 -> 0
A7: SC5 | C7: 0 | D7: =C7/1000 -> 0 | E7: 62 | F7: =D7/E7 -> 0 | G7: 6 | H7: =F7/G7 -> 0 | I7: 2978 | J7: =H7*I7 -> 0 | K7: =H7*1000 -> 0 | L7: =H7*$L$2 -> 0 | N7: =L7*1000 -> 0 | O7: =J7*1000 -> 0
A8: SC6 | C8: 6.4 | D8: =C8/1000 -> 0.0064 | E8: 62 | F8: =D8/E8 -> 0.00010322581 | G8: 6 | H8: =F8/G8 -> 1.7204301e-05 | I8: 2978 | J8: =H8*I8 -> 0.051234409 | K8: =H8*1000 -> 0.017204301 | L8: =H8*$L$2 -> 0.001343828 | N8: =L8*1000 -> 1.343828 | O8: =J8*1000 -> 51.234409
J9: =H9*I9 -> 0 | K9: =H9*1000 -> 0 | L9: =H9*$L$2 -> 0 | N9: =L9*1000 -> 0 | O9: =J9*1000 -> 0
A10: Manganese | J10: =H10*I10 -> 0 | K10: =H10*1000 -> 0 | L10: =H10*$L$2 -> 0 | N10: =L10*1000 -> 0 | O10: =J10*1000 -> 0 | P10: 0
A11: SC1 | B11: 110 | C11: 110 | D11: =C11/1000 -> 0.11 | E11: 54.938 | F11: =D11/E11 -> 0.0020022571 | G11: 15 | H11: =F11/G11 -> 0.00013348381 | I11: 2104 | J11: =H11*I11 -> 0.28084993 | K11: =H11*1000 -> 0.13348381 | L11: =H11*$L$2 -> 0.01042642 | N11: =L11*1000 -> 10.42642 | O11: =J11*1000 -> 280.84993 | P11: 142.97815
A12: SC2 | B12: 150 | C12: 150 | D12: =C12/1000 -> 0.15 | E12: 54.938 | F12: =D12/E12 -> 0.0027303506 | G12: 15 | H12: =F12/G12 -> 0.00018202337 | I12: 2104 | J12: =H12*I12 -> 0.38297717 | K12: =H12*1000 -> 0.18202337 | L12: =H12*$L$2 -> 0.014217846 | N12: =L12*1000 -> 14.217846 | O12: =J12*1000 -> 382.97717 | P12: 245.10539
A13: SC3 | B13: 54 | C13: 54 | D13: =C13/1000 -> 0.054 | E13: 54.938 | F13: =D13/E13 -> 0.00098292621 | G13: 15 | H13: =F13/G13 -> 6.5528414e-05 | I13: 2104 | J13: =H13*I13 -> 0.13787178 | K13: =H13*1000 -> 0.065528414 | L13: =H13*$L$2 -> 0.0051184244 | N13: =L13*1000 -> 5.1184244 | O13: =J13*1000 -> 137.87178 | P13: 0
A14: SC4 | B14: 65 | C14: 65 | D14: =C14/1000 -> 0.065 | E14: 54.938 | F14: =D14/E14 -> 0.0011831519 | G14: 15 | H14: =F14/G14 -> 7.8876794e-05 | I14: 2104 | J14: =H14*I14 -> 0.16595678 | K14: =H14*1000 -> 0.078876794 | L14: =H14*$L$2 -> 0.0061610664 | N14: =L14*1000 -> 6.1610664 | O14: =J14*1000 -> 165.95678 | P14: 28.084993
A15: SC5 | B15: 73 | C15: 73 | D15: =C15/1000 -> 0.073 | E15: 54.938 | F15: =D15/E15 -> 0.0013287706 | G15: 15 | H15: =F15/G15 -> 8.8584708e-05 | I15: 2104 | J15: =H15*I15 -> 0.18638222 | K15: =H15*1000 -> 0.088584708 | L15: =H15*$L$2 -> 0.0069193515 | N15: =L15*1000 -> 6.9193515 | O15: =J15*1000 -> 186.38222 | P15: 48.510442
A16: SC6 | B16: 161 | C16: 161 | D16: =C16/1000 -> 0.161 | E16: 54.938 | F16: =D16/E16 -> 0.0029305763 | G16: 15 | H16: =F16/G16 -> 0.00019537175 | I16: 2104 | J16: =H16*I16 -> 0.41106217 | K16: =H16*1000 -> 0.19537175 | L16: =H16*$L$2 -> 0.015260488 | N16: =L16*1000 -> 15.260488 | O16: =J16*1000 -> 411.06217 | P16: 273.19038
L17: =H17*$L$2 -> 0 | N17: =L17*1000 -> 0 | O17: =J17*1000 -> 0
A18: iron | L18: =H18*$L$2 -> 0 | N18: =L18*1000 -> 0 | O18: =J18*1000 -> 0 | P18: 0
A19: SC1 | B19: 4640 | C19: 4640 | D19: =C19/1000 -> 4.64 | E19: 55.845 | F19: =D19/E19 -> 0.083087116 | G19: 30 | H19: =F19/G19 -> 0.0027695705 | I19: 814.5 | J19: =H19*I19 -> 2.2558152 | K19: =H19*1000 -> 2.7695705 | L19: =H19*$L$2 -> 0.21633115 | N19: =L19*1000 -> 216.33115 | O19: =J19*1000 -> 2255.8152 | P19: 1205.6943
A20: SC2 | B20: 8830 | C20: 8830 | D20: =C20/1000 -> 8.83 | E20: 55.845 | F20: =D20/E20 -> 0.15811621 | G20: 30 | H20: =F20/G20 -> 0.0052705405 | I20: 814.5 | J20: =H20*I20 -> 4.2928552 | K20: =H20*1000 -> 5.2705405 | L20: =H20*$L$2 -> 0.41168192 | N20: =L20*1000 -> 411.68192 | O20: =J20*1000 -> 4292.8552 | P20: 3242.7344
A21: SC3 | B21: 3720 | C21: 3720 | D21: =C21/1000 -> 3.72 | E21: 55.845 | F21: =D21/E21 -> 0.066612947 | G21: 30 | H21: =F21/G21 -> 0.0022204316 | I21: 814.5 | J21: =H21*I21 -> 1.8085415 | K21: =H21*1000 -> 2.2204316 | L21: =H21*$L$2 -> 0.17343791 | N21: =L21*1000 -> 173.43791 | O21: =J21*1000 -> 1808.5415 | P21: 758.42063
A22: SC4 | B22: 3150 | C22: 3150 | D22: =C22/1000 -> 3.15 | E22: 55.845 | F22: =D22/E22 -> 0.056406124 | G22: 30 | H22: =F22/G22 -> 0.0018802041 | I22: 814.5 | J22: =H22*I22 -> 1.5314263 | K22: =H22*1000 -> 1.8802041 | L22: =H22*$L$2 -> 0.14686275 | N22: =L22*1000 -> 146.86275 | O22: =J22*1000 -> 1531.4263 | P22: 481.3054
A23: SC5 | B23: 3450 | C23: 3450 | D23: =C23/1000 -> 3.45 | E23: 55.845 | F23: =D23/E23 -> 0.061778136 | G23: 30 | H23: =F23/G23 -> 0.0020592712 | I23: 814.5 | J23: =H23*I23 -> 1.6772764 | K23: =H23*1000 -> 2.0592712 | L23: =H23*$L$2 -> 0.16084967 | N23: =L23*1000 -> 160.84967 | O23: =J23*1000 -> 1677.2764 | P23: 627.15552
A24: SC6 | B24: 2160 | C24: 2160 | D24: =C24/1000 -> 2.16 | E24: 55.845 | F24: =D24/E24 -> 0.038678485 | G24: 30 | H24: =F24/G24 -> 0.0012892828 | I24: 814.5 | J24: =H24*I24 -> 1.0501209 | K24: =H24*1000 -> 1.2892828 | L24: =H24*$L$2 -> 0.10070588 | N24: =L24*1000 -> 100.70588 | O24: =J24*1000 -> 1050.1209 | P24: 0
D25: =C25/1000 -> 0 | J25: =H25*I25 -> 0 | K25: =H25*1000 -> 0 | L25: =H25*$L$2 -> 0 | N25: =L25*1000 -> 0 | O25: =J25*1000 -> 0
A26: Sulphate | D26: =C26/1000 -> 0 | J26: =H26*I26 -> 0 | K26: =H26*1000 -> 0 | L26: =H26*$L$2 -> 0 | N26: =L26*1000 -> 0 | O26: =J26*1000 -> 0
A27: SC1 | C27: 52 | D27: =C27/1000 -> 0.052 | E27: 96.06 | F27: =D27/E27 -> 0.00054132834 | G27: 3.75 | H27: =F27/G27 -> 0.00014435422 | I27: 186 | J27: =H27*I27 -> 0.026849885 | K27: =H27*1000 -> 0.14435422 | L27: =H27*$L$2 -> 0.011275508 | N27: =L27*1000 -> 11.275508 | O27: =J27*1000 -> 26.849885
A28: SC2 | C28: 101 | D28: =C28/1000 -> 0.101 | E28: 96.06 | F28: =D28/E28 -> 0.0010514262 | G28: 3.75 | H28: =F28/G28 -> 0.00028038032 | I28: 186 | J28: =H28*I28 -> 0.052150739 | K28: =H28*1000 -> 0.28038032 | L28: =H28*$L$2 -> 0.021900507 | N28: =L28*1000 -> 21.900507 | O28: =J28*1000 -> 52.150739
A29: SC3 | C29: 244 | D29: =C29/1000 -> 0.244 | E29: 96.06 | F29: =D29/E29 -> 0.0025400791 | G29: 3.75 | H29: =F29/G29 -> 0.00067735443 | I29: 186 | J29: =H29*I29 -> 0.12598792 | K29: =H29*1000 -> 0.67735443 | L29: =H29*$L$2 -> 0.052908155 | N29: =L29*1000 -> 52.908155 | O29: =J29*1000 -> 125.98792
A30: SC4 | C30: 61 | D30: =C30/1000 -> 0.061 | E30: 96.06 | F30: =D30/E30 -> 0.00063501978 | G30: 3.75 | H30: =F30/G30 -> 0.00016933861 | I30: 186 | J30: =H30*I30 -> 0.031496981 | K30: =H30*1000 -> 0.16933861 | L30: =H30*$L$2 -> 0.013227039 | N30: =L30*1000 -> 13.227039 | O30: =J30*1000 -> 31.496981
A31: SC5 | C31: 142 | D31: =C31/1000 -> 0.142 | E31: 96.06 | F31: =D31/E31 -> 0.0014782428 | G31: 3.75 | H31: =F31/G31 -> 0.00039419807 | I31: 186 | J31: =H31*I31 -> 0.073320841 | K31: =H31*1000 -> 0.39419807 | L31: =H31*$L$2 -> 0.030790811 | N31: =L31*1000 -> 30.790811 | O31: =J31*1000 -> 73.320841
A32: SC6 | C32: 161 | D32: =C32/1000 -> 0.161 | E32: 96.06 | F32: =D32/E32 -> 0.0016760358 | G32: 3.75 | H32: =F32/G32 -> 0.00044694288 | I32: 186 | J32: =H32*I32 -> 0.083131376 | K32: =H32*1000 -> 0.44694288 | L32: =H32*$L$2 -> 0.034910709 | N32: =L32*1000 -> 34.910709 | O32: =J32*1000 -> 83.131376
J35: =H35*I35 -> 0 | K35: =H35*1000 -> 0 | L35: =H35*$L$2 -> 0 | N35: =L35*1000 -> 0 | O35: =J35*1000 -> 0
H36: =F36/G36 -> #DIV/0! | I36: 186 | J36: =H36*I36 -> #DIV/0! | K36: =H36*1000 -> #DIV/0! | L36: =H36*$L$2 -> #DIV/0! | N36: =L36*1000 -> #DIV/0! | O36: =J36*1000 -> #DIV/0!
H37: =F37/G37 -> #DIV/0! | I37: 186 | J37: =H37*I37 -> #DIV/0! | K37: =H37*1000 -> #DIV/0! | L37: =H37*$L$2 -> #DIV/0! | N37: =L37*1000 -> #DIV/0! | O37: =J37*1000 -> #DIV/0!
H38: =F38/G38 -> #DIV/0! | I38: 186 | J38: =H38*I38 -> #DIV/0! | K38: =H38*1000 -> #DIV/0! | L38: =H38*$L$2 -> #DIV/0! | N38: =L38*1000 -> #DIV/0! | O38: =J38*1000 -> #DIV/0!
H39: =F39/G39 -> #DIV/0! | I39: 186 | J39: =H39*I39 -> #DIV/0! | K39: =H39*1000 -> #DIV/0! | L39: =H39*$L$2 -> #DIV/0! | N39: =L39*1000 -> #DIV/0! | O39: =J39*1000 -> #DIV/0!
H40: =F40/G40 -> #DIV/0! | I40: 186 | J40: =H40*I40 -> #DIV/0! | K40: =H40*1000 -> #DIV/0! | L40: =H40*$L$2 -> #DIV/0! | N40: =L40*1000 -> #DIV/0! | O40: =J40*1000 -> #DIV/0!
H41: =F41/G41 -> #DIV/0! | I41: 186 | J41: =H41*I41 -> #DIV/0! | K41: =H41*1000 -> #DIV/0! | L41: =H41*$L$2 -> #DIV/0! | N41: =L41*1000 -> #DIV/0! | O41: =J41*1000 -> #DIV/0!
M57: total energy per sample | N57: total benzene oxidation capacity (mg benzene/kg)
...

Sheet mg_to_mole
A1: Soil properties | B1: Nitrate (mg/kg) | C1: Sulphates (mg/kg) | D1: Iron (mg/kg) | E1: Manganese (mg/kg) | F1: pH | G1: Conductivity (dS/m) | I1: Soil properties | J1: Nitrate (mmol/kg) | K1: Sulphates (mmol/kg) | L1: Iron (mmol/kg) | M1: Manganese (mmol/kg) | N1: pH | O1: Conductivity (dS/m) | P1: theoretical energy available if all electron acceptors are consumed for benzene oxidation (kJ)
A2: SC1 | B2: 7.8 | C2: 52 | D2: 4640 | E2: 110 | F2: 8.85 | G2: 0.084 | I2: SC1 | J2: 0.12579651 | K2: 0.54132834 | L2: 83.079678 | M2: 2.0022571 | N2: 8.85 | O2: 0.084 | P2: -4126.0731
A3: SC2 | B3: 9 | C3: 101 | D3: 8830 | E3: 150 | F3: 8.58 | G3: 0.123 | I3: SC2 | J3: 0.14514982 | K3: 1.0514262 | L3: 158.10206 | M3: 2.7303506 | N3: 8.58 | O3: 0.123 | P3: -6345.1727
A4: SC3 | B4: 0 | C4: 244 | D4: 3720 | E4: 54 | F4: 8.13 | G4: 0.149 | I4: SC3 | J4: 0 | K4: 2.5400791 | L4: 66.606983 | M4: 0.98292621 | N4: 8.13 | O4: 0.149 | P4: -2324.1646
A5: SC4 | B5: 0 | C5: 61 | D5: 3150 | E5: 65 | F5: 8.3 | G5: 0.064 | I5: SC4 | J5: 0 | K5: 0.63501978 | L5: 56.401074 | M5: 1.1831519 | N5: 8.3 | O5: 0.064 | P5: -2381.5605
A6: SC5 | B6: 0 | C6: 142 | D6: 3450 | E6: 73 | F6: 8.04 | G6: 0.068 | I6: SC5 | J6: 0 | K6: 1.4782428 | L6: 61.772605 | M6: 1.3287706 | N6: 8.04 | O6: 0.068 | P6: -2647.1982
A7: SC6 | B7: 6.4 | C7: 161 | D7: 2160 | E7: 161 | F7: 7.86 | G7: 0.068 | I7: SC6 | J7: 0.10321765 | K7: 1.6760358 | L7: 38.675022 | M7: 2.9305763 | N7: 7.86 | O7: 0.068 | P7: -4387.1373
C10: =7.8/62 -> 0.12580645
A13: Nitrate (mg/kg) | B13: Nitrate (g/kg) | C13: Molar mass (62.0049 g/mol) | D13: mol/kg | E13: mmol/kg | F13: Iron (mg/kg) | G13: Iron (g/kg) | H13: 55.85 g/mol. | I13: mol/kg | J13: mmol/kg
A14: 7.8 | B14: =A14/1000 -> 0.0078 | C14: 62.0049 | D14: =(B14)/(C14) -> 0.00012579651 | E14: =D14*1000 -> 0.12579651 | F14: 4640 | G14: =F14/1000 -> 4.64 | H14: 55.85 | I14: =(G14)/(H14) -> 0.083079678 | J14: =I14*1000 -> 83.079678
A15: 9 | B15: =A15/1000 -> 0.009 | C15: 62.0049 | D15: =(B15)/(C15) -> 0.00014514982 | E15: =D15*1000 -> 0.14514982 | F15: 8830 | G15: =F15/1000 -> 8.83 | H15: 55.85 | I15: =(G15)/(H15) -> 0.15810206 | J15: =I15*1000 -> 158.10206
A16: 0 | B16: =A16/1000 -> 0 | C16: 62.0049 | D16: =(B16)/(C16) -> 0 | E16: =D16*1000 -> 0 | F16: 3720 | G16: =F16/1000 -> 3.72 | H16: 55.85 | I16: =(G16)/(H16) -> 0.066606983 | J16: =I16*1000 -> 66.606983
A17: 0 | B17: =A17/1000 -> 0 | C17: 62.0049 | D17: =(B17)/(C17) -> 0 | E17: =D17*1000 -> 0 | F17: 3150 | G17: =F17/1000 -> 3.15 | H17: 55.85 | I17: =(G17)/(H17) -> 0.056401074 | J17: =I17*1000 -> 56.401074
A18: 0 | B18: =A18/1000 -> 0 | C18: 62.0049 | D18: =(B18)/(C18) -> 0 | E18: =D18*1000 -> 0 | F18: 3450 | G18: =F18/1000 -> 3.45 | H18: 55.85 | I18: =(G18)/(H18) -> 0.061772605 | J18: =I18*1000 -> 61.772605
A19: 6.4 | B19: =A19/1000 -> 0.0064 | C19: 62.0049 | D19: =(B19)/(C19) -> 0.00010321765 | E19: =D19*1000 -> 0.10321765 | F19: 2160 | G19: =F19/1000 -> 2.16 | H19: 55.85 | I19: =(G19)/(H19) -> 0.038675022 | J19: =I19*1000 -> 38.675022
A21: Sulphates (mg/kg) | B21: Sulphates (g/kg) | C21: 96,06 g/mol | D21: mol/kg | E21: mmol/kg | F21: Manganese (mg/kg) | G21: Manganese (g/kg) | H21: 54.938049 g/mol | I21: mol/kg | J21: mmol/kg
A22: 52 | B22: =A22/1000 -> 0.052 | C22: 96.06 | D22: =(B22)/(C22) -> 0.00054132834 | E22: =D22*1000 -> 0.54132834 | F22: 110 | G22: =F22/1000 -> 0.11 | H22: 54.938 | I22: =(G22)/(H22) -> 0.0020022571 | J22: =I22*1000 -> 2.0022571
A23: 101 | B23: =A23/1000 -> 0.101 | C23: 96.06 | D23: =(B23)/(C23) -> 0.0010514262 | E23: =D23*1000 -> 1.0514262 | F23: 150 | G23: =F23/1000 -> 0.15 | H23: 54.938 | I23: =(G23)/(H23) -> 0.0027303506 | J23: =I23*1000 -> 2.7303506
A24: 244 | B24: =A24/1000 -> 0.244 | C24: 96.06 | D24: =(B24)/(C24) -> 0.0025400791 | E24: =D24*1000 -> 2.5400791 | F24: 54 | G24: =F24/1000 -> 0.054 | H24: 54.938 | I24: =(G24)/(H24) -> 0.00098292621 | J24: =I24*1000 -> 0.98292621
A25: 61 | B25: =A25/1000 -> 0.061 | C25: 96.06 | D25: =(B25)/(C25) -> 0.00063501978 | E25: =D25*1000 -> 0.63501978 | F25: 65 | G25: =F25/1000 -> 0.065 | H25: 54.938 | I25: =(G25)/(H25) -> 0.0011831519 | J25: =I25*1000 -> 1.1831519
A26: 142 | B26: =A26/1000 -> 0.142 | C26: 96.06 | D26: =(B26)/(C26) -> 0.0014782428 | E26: =D26*1000 -> 1.4782428 | F26: 73 | G26: =F26/1000 -> 0.073 | H26: 54.938 | I26: =(G26)/(H26) -> 0.0013287706 | J26: =I26*1000 -> 1.3287706
A27: 161 | B27: =A27/1000 -> 0.161 | C27: 96.06 | D27: =(B27)/(C27) -> 0.0016760358 | E27: =D27*1000 -> 1.6760358 | F27: 161 | G27: =F27/1000 -> 0.161 | H27: 54.938 | I27: =(G27)/(H27) -> 0.0029305763 | J27: =I27*1000 -> 2.9305763
A29: to electron acceptor capacity (number of electrons per mol) | P29: Nitrate in SC1: 7.8 mg.kg-1 = 0.0078 g.kg-1
C30: Number of electrons accepted per mole (in mol) | D30: Total mmol electrons 'acceptable' for this compound | G30: Number of electrons accepted per mole (in mol) | H30: Total mmol electrons 'acceptable' for this compound | P30: Molar mass nitrate = 62 g.mol-1
A31: Soil properties | B31: Nitrate (mmol/kg) | C31: 5 | F31: Iron (mmol/kg) | G31: 1 | P31: Moles of nitrate per kg dry soil: = 0.0078 g/ 62 g.mol-1= 0,000125806 Moles. kg-1
A32: SC1 | B32: 0.12579651 | C32: 5 | D32: =B32*C32 -> 0.62898255 | F32: 83.079678 | G32: 1 | H32: =F32*G32 -> 83.079678 | P32: Number of moles nitrate consumed per mole of benzene, based on Stoichiometric equation: 6
A33: SC2 | B33: 0.14514982 | C33: 5 | D33: =B33*C33 -> 0.72574909 | F33: 158.10206 | G33: 1 | H33: =F33*G33 -> 158.10206 | P33: How many moles of benzene can be oxidised x moles of nitrate:
A34: SC3 | B34: 0 | C34: 5 | D34: =B34*C34 -> 0 | F34: 66.606983 | G34: 1 | H34: =F34*G34 -> 66.606983 | P34: 1,25806 x 10-4 Moles. kg-1 nitrate / 6 = 2,09677 x 10-5 Moles. kg-1
A35: SC4 | B35: 0 | C35: 5 | D35: =B35*C35 -> 0 | F35: 56.401074 | G35: 1 | H35: =F35*G35 -> 56.401074 | P35: Molar mass benzene = 78.11 x 103 mg.mol-1
A36: SC5 | B36: 0 | C36: 5 | D36: =B36*C36 -> 0 | F36: 61.772605 | G36: 1 | H36: =F36*G36 -> 61.772605 | P36: Covert moles of benzene to mg.kg-1
A37: SC6 | B37: 0.10321765 | C37: 5 | D37: =B37*C37 -> 0.51608824 | F37: 38.675022 | G37: 1 | H37: =F37*G37 -> 38.675022 | P37: 2,09677 x 10-5 Moles. kg-1 * 78.11 x 103 mg.mol-1 = 1.638 mg.kg-1
C39: Number of electrons accepted per mole (in mol)
B40: Sulphates (mmol/kg) | C40: 8 | F40: Manganese (mmol/kg) | G40: 2
B41: 0.54132834 | C41: 8 | D41: =B41*C41 -> 4.3306267 | F41: 2.0022571 | G41: 2 | H41: =F41*G41 -> 4.0045142
B42: 1.0514262 | C42: 8 | D42: =B42*C42 -> 8.4114095 | F42: 2.7303506 | G42: 2 | H42: =F42*G42 -> 5.4607012
B43: 2.5400791 | C43: 8 | D43: =B43*C43 -> 20.320633 | F43: 0.98292621 | G43: 2 | H43: =F43*G43 -> 1.9658524
B44: 0.63501978 | C44: 8 | D44: =B44*C44 -> 5.0801582 | F44: 1.1831519 | G44: 2 | H44: =F44*G44 -> 2.3663038
B45: 1.4782428 | C45: 8 | D45: =B45*C45 -> 11.825942 | F45: 1.3287706 | G45: 2 | H45: =F45*G45 -> 2.6575412
B46: 1.6760358 | C46: 8 | D46: =B46*C46 -> 13.408286 | F46: 2.9305763 | G46: 2 | H46: =F46*G46 -> 5.8611526
K55: https://www.researchgate.net/figure/Order-of-utilization-of-electron-acceptor-half-reactions-in-soils-and-the-associated_tbl1_271943847
...

Sheet Wetland study
B3: iron2_mg_l | C3: manganese2_mg_l | D3: nitrate_N_mg_l | E3: sulfate_mg_l
A4: T0 | B4: 0.3 | C4: 0.9 | D4: 0.017 | E4: 73
A5: T1 | B5: 1.9 | C5: 1.1 | D5: 0.017 | E5: 78
A6: T2 | B6: 1.2 | C6: 0.9 | D6: 0.017 | E6: 81
A7: T3 | B7: 0.5 | C7: 0.8 | D7: 0.017 | E7: 82
A8: T4 | B8: 0.6 | C8: 0.8 | D8: 0.017 | E8: 87
A9: T5 | B9: 20 | C9: 1.7 | D9: 0.017 | E9: 79
A10: T6 | B10: 4.2 | C10: 1.4 | D10: 0.017 | E10: 140
A11: T7 | B11: 0.02 | C11: 0.05 | D11: 0.017 | E11: 25
A12: T8 | B12: 1.5 | C12: 0.8 | D12: 0.017 | E12: 72
C13: manganese2_mg_l
B14: T0 | C14: 0.9
B15: T1 | C15: 1.1
B16: T2 | C16: 0.9
B17: T3 | C17: 0.8
B18: T4 | C18: 0.8
B19: T5 | C19: 1.7
B20: T6 | C20: 1.4
B21: T7 | C21: 0.05
B22: T8 | C22: 0.8
D24: nitrate_N_mg_l
C25: T0 | D25: 0.017
C26: T1 | D26: 0.017
C27: T2 | D27: 0.017
C28: T3 | D28: 0.017
C29: T4 | D29: 0.017
C30: T5 | D30: 0.017
C31: T6 | D31: 0.017
C32: T7 | D32: 0.017
C33: T8 | D33: 0.017
E34: sulfate_mg_l
D35: T0 | E35: 73
D36: T1 | E36: 78
D37: T2 | E37: 81
D38: T3 | E38: 82
D39: T4 | E39: 87
D40: T5 | E40: 79
D41: T6 | E41: 140
D42: T7 | E42: 25
D43: T8 | E43: 72

Sheet iron_sulfur_cycle
A17: iron2_precipated_due_to_sulphate_reduction_mg_l | B17: iron2_precipated_due_to_sulphate_reduction_no_negative_values_mg_l | C17: iron2_mg_l | D17: iron2_measured_mmoles_l | E17: iron2_measured_electron_acceptor_capacity_mmol_e | F17: total_iron2_mg_l | G17: iron2_total_mmoles_l | H17: iron2_total_electron_acceptor_capacity_mmol_e
A18: 0 | C18: 0.3 | D18: 0.0053715309 | E18: 0.0053715309 | F18: 0.3 | G18: 0.0053715309 | H18: 0.0053715309
A19: 21.508224 | B19: 21.508224 | C19: 5.3 | D19: 0.094897046 | E19: 0.094897046 | F19: 26.808224 | G19: 0.48000401 | H19: 0.48000401
A20: 20.926921 | B20: 20.926921 | C20: 6.3 | D20: 0.11280215 | E20: 0.11280215 | F20: 27.226921 | G20: 0.48750082 | H20: 0.48750082
A23: manganese2_mg_l | B23: manganese2_mmoles_l | C23: manganese2_electron_acceptor_capacity_mmol_e_l | D23: Ratio_iron_manganese2_in_mmoles_l_precipitation | E23: Ratio_iron_manganese2_in_mmoles_e_l_metabolic | F23: combined_total_reduced_dissolved_metals_mg_l | G23: combined_total_reduced_dissolved_metals_mmol_e
A24: 0.9 | B24: 0.016384489 | C24: 0.032768979 | D24: 0.32784244 | E24: 0.16392122 | F24: 1.2 | G24: 0.03814051
A25: 3.8 | B25: 0.069178955 | C25: 0.13835791 | D25: 6.9385843 | E25: 3.4692921 | F25: 30.608224 | G25: 0.61836192
A26: 3.7 | B26: 0.067358456 | C26: 0.13471691 | D26: 7.2374108 | E26: 3.6187054 | F26: 30.926921 | G26: 0.62221773

Sheet Electron_Redox_Calculations
A1: Soil properties | B1: Nitrate (mmol/kg) | C1: Sulphates (mmol/kg) | D1: Iron (mmol/kg) | E1: Manganese (mmol/kg) | F1: Total mol of electrons acceptors availabled'
A2: SC1 | B2: 0.12579651 | C2: 0.54132834 | D2: 83.079678 | E2: 2.0022571 | F2: =D11+D20+H11+H20 -> 92.043801
A3: SC2 | B3: 0.14514982 | C3: 1.0514262 | D3: 158.10206 | E3: 2.7303506 | F3: =D12+D21+H12+H21 -> 172.69992
A4: SC3 | B4: 0 | C4: 2.5400791 | D4: 66.606983 | E4: 0.98292621 | F4: =D13+D22+H13+H22 -> 88.893468
A5: SC4 | B5: 0 | C5: 0.63501978 | D5: 56.401074 | E5: 1.1831519 | F5: =D14+D23+H14+H23 -> 63.847536
A6: SC5 | B6: 0 | C6: 1.4782428 | D6: 61.772605 | E6: 1.3287706 | F6: =D15+D24+H15+H24 -> 76.256089
A7: SC6 | B7: 0.10321765 | C7: 1.6760358 | D7: 38.675022 | E7: 2.9305763 | F7: =D16+D25+H16+H25 -> 58.46055
C9: Number of electrons accepted per mole (in mol) | D9: Total mmol electrons 'acceptable' for this compound | E9: Gibs free energy to oxidise 1 benzene using this electron acceptor | G9: Number of electrons accepted per mole (in mol) | H9: Total mmol electrons 'acceptable' for this compound
A10: Soil properties | B10: Nitrate (mmol/kg) | C10: 5 | E10: -2.978 | F10: Iron (mmol/kg) | G10: 1
A11: SC1 | B11: 0.12579651 | C11: 5 | D11: =B11*C11 -> 0.62898255 | E11: -2.978 | F11: 83.079678 | G11: 1 | H11: =F11*G11 -> 83.079678
A12: SC2 | B12: 0.14514982 | C12: 5 | D12: =B12*C12 -> 0.72574909 | E12: -2.978 | F12: 158.10206 | G12: 1 | H12: =F12*G12 -> 158.10206
A13: SC3 | B13: 0 | C13: 5 | D13: =B13*C13 -> 0 | E13: -2.978 | F13: 66.606983 | G13: 1 | H13: =F13*G13 -> 66.606983
A14: SC4 | B14: 0 | C14: 5 | D14: =B14*C14 -> 0 | E14: -2.978 | F14: 56.401074 | G14: 1 | H14: =F14*G14 -> 56.401074
A15: SC5 | B15: 0 | C15: 5 | D15: =B15*C15 -> 0 | E15: -2.978 | F15: 61.772605 | G15: 1 | H15: =F15*G15 -> 61.772605
A16: SC6 | B16: 0.10321765 | C16: 5 | D16: =B16*C16 -> 0.51608824 | E16: -2.978 | F16: 38.675022 | G16: 1 | H16: =F16*G16 -> 38.675022
C18: Number of electrons accepted per mole (in mol)
B19: Sulphates (mmol/kg) | C19: 8 | F19: Manganese (mmol/kg) | G19: 2
B20: 0.54132834 | C20: 8 | D20: =B20*C20 -> 4.3306267 | F20: 2.0022571 | G20: 2 | H20: =F20*G20 -> 4.0045142
B21: 1.0514262 | C21: 8 | D21: =B21*C21 -> 8.4114095 | F21: 2.7303506 | G21: 2 | H21: =F21*G21 -> 5.4607012
B22: 2.5400791 | C22: 8 | D22: =B22*C22 -> 20.320633 | F22: 0.98292621 | G22: 2 | H22: =F22*G22 -> 1.9658524
B23: 0.63501978 | C23: 8 | D23: =B23*C23 -> 5.0801582 | F23: 1.1831519 | G23: 2 | H23: =F23*G23 -> 2.3663038
B24: 1.4782428 | C24: 8 | D24: =B24*C24 -> 11.825942 | F24: 1.3287706 | G24: 2 | H24: =F24*G24 -> 2.6575412
B25: 1.6760358 | C25: 8 | D25: =B25*C25 -> 13.408286 | F25: 2.9305763 | G25: 2 | H25: =F25*G25 -> 5.8611526
F30: electrons resulting from benzene biodegradation: 30 | K30: electrons resulting from benzene biodegradation: 30
C31: Number of electrons accepted per mole (in mol) | D31: Total mmol electrons 'acceptable' for this compound | E31: Gibs free energy to oxidise 1 benzene using this electron acceptor | F31: How much mole is consumed per mole of benzene | I31: Number of electrons accepted per mole (in mol) | J31: Total mmol electrons 'acceptable' for this compound | K31: Gibs free energy to oxidise 1 benzene using this electron acceptor | L31: How much mole is consumed per mole of benzene
A32: Soil properties | B32: Nitrate (mmol/kg) | C32: 5 | E32: -2.978 | F32: 6 | H32: Iron (mmol/kg) | I32: 1 | K32: -525 | L32: 30
A33: SC1 | B33: 0.12579651 | C33: 5 | D33: =B33*C33 -> 0.62898255 | E33: -2.978 | F33: 6 | H33: 83.079678 | I33: 1 | J33: =H33*I33 -> 83.079678 | K33: -525 | L33: 30
A34: SC2 | B34: 0.14514982 | C34: 5 | D34: =B34*C34 -> 0.72574909 | E34: -2.978 | F34: 6 | H34: 158.10206 | I34: 1 | J34: =H34*I34 -> 158.10206 | K34: -525 | L34: 30
A35: SC3 | B35: 0 | C35: 5 | D35: =B35*C35 -> 0 | E35: -2.978 | F35: 6 | H35: 66.606983 | I35: 1 | J35: =H35*I35 -> 66.606983 | K35: -525 | L35: 30
A36: SC4 | B36: 0 | C36: 5 | D36: =B36*C36 -> 0 | E36: -2.978 | F36: 6 | H36: 56.401074 | I36: 1 | J36: =H36*I36 -> 56.401074 | K36: -525 | L36: 30
A37: SC5 | B37: 0 | C37: 5 | D37: =B37*C37 -> 0 | E37: -2.978 | F37: 6 | H37: 61.772605 | I37: 1 | J37: =H37*I37 -> 61.772605 | K37: -525 | L37: 30
A38: SC6 | B38: 0.10321765 | C38: 5 | D38: =B38*C38 -> 0.51608824 | E38: -2.978 | F38: 6 | H38: 38.675022 | I38: 1 | J38: =H38*I38 -> 38.675022 | K38: -525 | L38: 30
C40: Number of electrons accepted per mole (in mol) | F40: electrons resulting from benzene biodegradation: 30 | K40: electrons resulting from benzene biodegradation: 30
B41: Sulphates (mmol/kg) | C41: 8 | E41: -106 | F41: 3.75 | H41: Manganese (mmol/kg) | I41: 2 | K41: -2104 | L41: 15
B42: 0.54132834 | C42: 8 | D42: =B42*C42 -> 4.3306267 | E42: -106 | F42: 3.75 | H42: 2.0022571 | I42: 2 | J42: =H42*I42 -> 4.0045142 | K42: -2104 | L42: 15
B43: 1.0514262 | C43: 8 | D43: =B43*C43 -> 8.4114095 | E43: -106 | F43: 3.75 | H43: 2.7303506 | I43: 2 | J43: =H43*I43 -> 5.4607012 | K43: -2104 | L43: 15
B44: 2.5400791 | C44: 8 | D44: =B44*C44 -> 20.320633 | E44: -106 | F44: 3.75 | H44: 0.98292621 | I44: 2 | J44: =H44*I44 -> 1.9658524 | K44: -2104 | L44: 15
B45: 0.63501978 | C45: 8 | D45: =B45*C45 -> 5.0801582 | E45: -106 | F45: 3.75 | H45: 1.1831519 | I45: 2 | J45: =H45*I45 -> 2.3663038 | K45: -2104 | L45: 15
B46: 1.4782428 | C46: 8 | D46: =B46*C46 -> 11.825942 | E46: -106 | F46: 3.75 | H46: 1.3287706 | I46: 2 | J46: =H46*I46 -> 2.6575412 | K46: -2104 | L46: 15
B47: 1.6760358 | C47: 8 | D47: =B47*C47 -> 13.408286 | E47: -106 | F47: 3.75 | H47: 2.9305763 | I47: 2 | J47: =H47*I47 -> 5.8611526 | K47: -2104 | L47: 15
...
